Traceback (most recent call last):
  File "/home/codespace/.local/lib/python3.12/site-packages/jupyter_core/utils/__init__.py", line 154, in wrapped
    asyncio.get_running_loop()
RuntimeError: no running event loop

During handling of the above exception, another exception occurred:

Traceback (most recent call last):
  File "/usr/local/python/3.12.1/lib/python3.12/site-packages/jupyter_cache/executors/utils.py", line 58, in single_nb_execution
    executenb(
  File "/home/codespace/.local/lib/python3.12/site-packages/nbclient/client.py", line 1319, in execute
    return NotebookClient(nb=nb, resources=resources, km=km, **kwargs).execute()
           ^^^^^^^^^^^^^^^^^^^^^^^^^^^^^^^^^^^^^^^^^^^^^^^^^^^^^^^^^^^^^^^^^^^^^
  File "/home/codespace/.local/lib/python3.12/site-packages/jupyter_core/utils/__init__.py", line 158, in wrapped
    return loop.run_until_complete(inner)
           ^^^^^^^^^^^^^^^^^^^^^^^^^^^^^^
  File "/usr/local/python/3.12.1/lib/python3.12/asyncio/base_events.py", line 684, in run_until_complete
    return future.result()
           ^^^^^^^^^^^^^^^
  File "/home/codespace/.local/lib/python3.12/site-packages/nbclient/client.py", line 709, in async_execute
    await self.async_execute_cell(
  File "/home/codespace/.local/lib/python3.12/site-packages/nbclient/client.py", line 1062, in async_execute_cell
    await self._check_raise_for_error(cell, cell_index, exec_reply)
  File "/home/codespace/.local/lib/python3.12/site-packages/nbclient/client.py", line 918, in _check_raise_for_error
    raise CellExecutionError.from_cell_and_msg(cell, exec_reply_content)
nbclient.exceptions.CellExecutionError: An error occurred while executing the following cell:
------------------
import matplotlib.pyplot as plt

# Prompt user for image nameâ€‹
image_name = input('Enter image name (with extension): ')
#base image: "spiderPete.jpg"
# Read the image using matplotlibâ€‹
image = plt.imread(image_name)

# Display the imageâ€‹
plt.figure()
plt.imshow(image)
plt.title('Spider Pete')
plt.xlabel('It is a spider')  # Appropriate label
plt.ylabel('It is Pete')  # Appropriate label if needed

# Show the plotâ€‹

plt.show()
------------------


[31m---------------------------------------------------------------------------[39m
[31mStdinNotImplementedError[39m                  Traceback (most recent call last)
[36mCell[39m[36m [39m[32mIn[1][39m[32m, line 4[39m
[32m      1[39m [38;5;28;01mimport[39;00m[38;5;250m [39m[34;01mmatplotlib[39;00m[34;01m.[39;00m[34;01mpyplot[39;00m[38;5;250m [39m[38;5;28;01mas[39;00m[38;5;250m [39m[34;01mplt[39;00m
[32m      3[39m [38;5;66;03m# Prompt user for image nameâ€‹[39;00m
[32m----> [39m[32m4[39m image_name = [38;5;28;43minput[39;49m[43m([49m[33;43m'[39;49m[33;43mEnter image name (with extension): [39;49m[33;43m'[39;49m[43m)[49m
[32m      5[39m [38;5;66;03m#base image: "spiderPete.jpg"[39;00m
[32m      6[39m [38;5;66;03m# Read the image using matplotlibâ€‹[39;00m
[32m      7[39m image = plt.imread(image_name)

[36mFile [39m[32m~/.local/lib/python3.12/site-packages/ipykernel/kernelbase.py:1281[39m, in [36mKernel.raw_input[39m[34m(self, prompt)[39m
[32m   1279[39m [38;5;28;01mif[39;00m [38;5;129;01mnot[39;00m [38;5;28mself[39m._allow_stdin:
[32m   1280[39m     msg = [33m"[39m[33mraw_input was called, but this frontend does not support input requests.[39m[33m"[39m
[32m-> [39m[32m1281[39m     [38;5;28;01mraise[39;00m StdinNotImplementedError(msg)
[32m   1282[39m [38;5;28;01mreturn[39;00m [38;5;28mself[39m._input_request(
[32m   1283[39m     [38;5;28mstr[39m(prompt),
[32m   1284[39m     [38;5;28mself[39m._parent_ident[[33m"[39m[33mshell[39m[33m"[39m],
[32m   1285[39m     [38;5;28mself[39m.get_parent([33m"[39m[33mshell[39m[33m"[39m),
[32m   1286[39m     password=[38;5;28;01mFalse[39;00m,
[32m   1287[39m )

[31mStdinNotImplementedError[39m: raw_input was called, but this frontend does not support input requests.

